<?xml version="1.0" encoding="utf-8"?>
<!-- This URDF was automatically created by SolidWorks to URDF Exporter! Originally created by Stephen Brawner (brawner@gmail.com) 
     Commit Version: 1.6.0-1-g15f4949  Build Version: 1.6.7594.29634
     For more information, please see http://wiki.ros.org/sw_urdf_exporter -->


<robot xmlns:xacro="http://ros.org/wiki/xacro" name="workbench_table">

    <xacro:macro name="workbench_table" params="prefix">

        <!-- mount the workbench to the robot -->

        <link
            name="${prefix}workbench_base">
            <visual>
            <origin
                xyz="-0.25 -.943 0"
                rpy="0 0 0" />
            <geometry>
                <mesh
                filename="package://vention_conveyor_description/meshes/workbench_base.STL" />
                <!-- <box size="2 2 1"/> -->
            </geometry>
            <material
                name="blue">
                <color
                rgba="0.33725 0.52941 0.75686 1" />
            </material>
            </visual>
            <collision>
            <origin
                xyz="-0.25 -.943 0"
                rpy="0 0 0" />
            <geometry>
                <mesh
                filename="package://vention_conveyor_description/meshes/workbench_base.STL" />
            </geometry>
            </collision>
        </link>


        <joint name="${prefix}workbench_joint" type="prismatic">
            <parent link="${prefix}workbench_base"/>
            <child link="${prefix}workbench_mount"/>
            <!-- Here we enter the joint position just defined before -->
            <origin xyz="0 -0.36 1.01" rpy="0 0 0"/> <!-- this y doesn't match actuall length, need to change later-->
            <!-- Here we define the axis along which the geometry is moved -->
            <axis xyz="0 1 0"/>
            <!-- Here we define the joint's upper and lower limits -->
            <limit effort="1000.0" lower="0" upper="0.71" velocity="0.1"/>
        </joint>

        <link name="${prefix}workbench_mount">
            <visual>
                <geometry>
                    <mesh
                    filename="package://vention_conveyor_description/meshes/workbench_mount.STL" />
                </geometry>
                <origin
                xyz="-.09 -.09 0"
                rpy="0 0 0" />
                <material name="">
                    <color
                    rgba="0.33725 0.52941 1 1" />
                </material>
            </visual>
            <collision>
                <geometry>
                    <mesh
                    filename="package://vention_conveyor_description/meshes/workbench_mount.STL" />
                </geometry>
                <origin
                xyz="-.09 -.09 0"
                rpy="0 0 0" />
            </collision>
        </link>

    </xacro:macro>
</robot>